Workbook

Sheet Expenses
A1: Date | B1: Item | C1: Category | D1: Amount | E1: Paid By | F1: Split | G1: Payment | H1: Impulse? | I1: Month | J1: Notes | K1: You ₹ | L1: Wife ₹ | M1: _effYou | N1: _effWife
I2: =IF($A2="","",TEXT($A2,"YYYY-MM")) | M2: =IF($A2="","",IF(AND($K2<>"",$L2<>""),$K2,IF($F2="You",$D2,IF($F2="Wife",0,IF($F2="Shared",$D2/2,0))))) | N2: =IF($A2="","",IF(AND($K2<>"",$L2<>""),$L2,IF($F2="You",0,IF($F2="Wife",$D2,IF($F2="Shared",$D2/2,0)))))
I3: =IF($A3="","",TEXT($A3,"YYYY-MM")) | M3: =IF($A3="","",IF(AND($K3<>"",$L3<>""),$K3,IF($F3="You",$D3,IF($F3="Wife",0,IF($F3="Shared",$D3/2,0))))) | N3: =IF($A3="","",IF(AND($K3<>"",$L3<>""),$L3,IF($F3="You",0,IF($F3="Wife",$D3,IF($F3="Shared",$D3/2,0)))))
I4: =IF($A4="","",TEXT($A4,"YYYY-MM")) | M4: =IF($A4="","",IF(AND($K4<>"",$L4<>""),$K4,IF($F4="You",$D4,IF($F4="Wife",0,IF($F4="Shared",$D4/2,0))))) | N4: =IF($A4="","",IF(AND($K4<>"",$L4<>""),$L4,IF($F4="You",0,IF($F4="Wife",$D4,IF($F4="Shared",$D4/2,0)))))
I5: =IF($A5="","",TEXT($A5,"YYYY-MM")) | M5: =IF($A5="","",IF(AND($K5<>"",$L5<>""),$K5,IF($F5="You",$D5,IF($F5="Wife",0,IF($F5="Shared",$D5/2,0))))) | N5: =IF($A5="","",IF(AND($K5<>"",$L5<>""),$L5,IF($F5="You",0,IF($F5="Wife",$D5,IF($F5="Shared",$D5/2,0)))))
I6: =IF($A6="","",TEXT($A6,"YYYY-MM")) | M6: =IF($A6="","",IF(AND($K6<>"",$L6<>""),$K6,IF($F6="You",$D6,IF($F6="Wife",0,IF($F6="Shared",$D6/2,0))))) | N6: =IF($A6="","",IF(AND($K6<>"",$L6<>""),$L6,IF($F6="You",0,IF($F6="Wife",$D6,IF($F6="Shared",$D6/2,0)))))
I7: =IF($A7="","",TEXT($A7,"YYYY-MM")) | M7: =IF($A7="","",IF(AND($K7<>"",$L7<>""),$K7,IF($F7="You",$D7,IF($F7="Wife",0,IF($F7="Shared",$D7/2,0))))) | N7: =IF($A7="","",IF(AND($K7<>"",$L7<>""),$L7,IF($F7="You",0,IF($F7="Wife",$D7,IF($F7="Shared",$D7/2,0)))))
I8: =IF($A8="","",TEXT($A8,"YYYY-MM")) | M8: =IF($A8="","",IF(AND($K8<>"",$L8<>""),$K8,IF($F8="You",$D8,IF($F8="Wife",0,IF($F8="Shared",$D8/2,0))))) | N8: =IF($A8="","",IF(AND($K8<>"",$L8<>""),$L8,IF($F8="You",0,IF($F8="Wife",$D8,IF($F8="Shared",$D8/2,0)))))
I9: =IF($A9="","",TEXT($A9,"YYYY-MM")) | M9: =IF($A9="","",IF(AND($K9<>"",$L9<>""),$K9,IF($F9="You",$D9,IF($F9="Wife",0,IF($F9="Shared",$D9/2,0))))) | N9: =IF($A9="","",IF(AND($K9<>"",$L9<>""),$L9,IF($F9="You",0,IF($F9="Wife",$D9,IF($F9="Shared",$D9/2,0)))))
I10: =IF($A10="","",TEXT($A10,"YYYY-MM")) | M10: =IF($A10="","",IF(AND($K10<>"",$L10<>""),$K10,IF($F10="You",$D10,IF($F10="Wife",0,IF($F10="Shared",$D10/2,0))))) | N10: =IF($A10="","",IF(AND($K10<>"",$L10<>""),$L10,IF($F10="You",0,IF($F10="Wife",$D10,IF($F10="Shared",$D10/2,0)))))
I11: =IF($A11="","",TEXT($A11,"YYYY-MM")) | M11: =IF($A11="","",IF(AND($K11<>"",$L11<>""),$K11,IF($F11="You",$D11,IF($F11="Wife",0,IF($F11="Shared",$D11/2,0))))) | N11: =IF($A11="","",IF(AND($K11<>"",$L11<>""),$L11,IF($F11="You",0,IF($F11="Wife",$D11,IF($F11="Shared",$D11/2,0)))))
I12: =IF($A12="","",TEXT($A12,"YYYY-MM")) | M12: =IF($A12="","",IF(AND($K12<>"",$L12<>""),$K12,IF($F12="You",$D12,IF($F12="Wife",0,IF($F12="Shared",$D12/2,0))))) | N12: =IF($A12="","",IF(AND($K12<>"",$L12<>""),$L12,IF($F12="You",0,IF($F12="Wife",$D12,IF($F12="Shared",$D12/2,0)))))
I13: =IF($A13="","",TEXT($A13,"YYYY-MM")) | M13: =IF($A13="","",IF(AND($K13<>"",$L13<>""),$K13,IF($F13="You",$D13,IF($F13="Wife",0,IF($F13="Shared",$D13/2,0))))) | N13: =IF($A13="","",IF(AND($K13<>"",$L13<>""),$L13,IF($F13="You",0,IF($F13="Wife",$D13,IF($F13="Shared",$D13/2,0)))))
... I500: =IF($A500="","",TEXT($A500,"YYYY-MM")) | M500: =IF($A500="","",IF(AND($K500<>"",$L500<>""),$K500,IF($F500="You",$D500,IF($F500="Wife",0,IF($F500="Shared",$D500/2,0))))) | N500: =IF($A500="","",IF(AND($K500<>"",$L500<>""),$L500,IF($F500="You",0,IF($F500="Wife",$D500,IF($F500="Shared",$D500/2,0)))))

Sheet Dashboard
B2: Household Expense Dashboard
B3: Live -- updates as rows arrive. Categories follow the Settings tab.
B5: Total Spend | D5: This Month | F5: Avg / Month | H5: Projected Year
B6: =SUM(Expenses!$D$2:$D$500) | D6: =SUMIF(Expenses!$I$2:$I$500,TEXT(TODAY(),"YYYY-MM"),Expenses!$D$2:$D$500) | F6: =IFERROR(SUM(Expenses!$D$2:$D$500)/MAX(1,SUMPRODUCT((Expenses!$I$2:$I$500<>"")/COUNTIF(Expenses!$I$2:$I$500,Expenses!$I$2:$I$500&""))),0) | H6: =F6*12
B8: By Category | C8: Total | D8: % Spend | E8: Yr Projection | G8: Individual | H8: Paid | I8: Fair Share*
B9: =IF(Settings!B3="","",Settings!B3) | C9: =IF($B9="","",SUMIF(Expenses!$C$2:$C$500,$B9,Expenses!$D$2:$D$500)) | D9: =IF($B9="","",IFERROR($C9/SUM(Expenses!$D$2:$D$500),0)) | E9: =IF($B9="","",$C9*(12/MAX(1,SUMPRODUCT((Expenses!$I$2:$I$500<>"")/COUNTIF(Expenses!$I$2:$I$500,Expenses!$I$2:$I$500&""))))) | G9: You | H9: =SUMIF(Expenses!$E$2:$E$500,"You",Expenses!$D$2:$D$500) | I9: =SUM(Expenses!$M$2:$M$500)
B10: =IF(Settings!B4="","",Settings!B4) | C10: =IF($B10="","",SUMIF(Expenses!$C$2:$C$500,$B10,Expenses!$D$2:$D$500)) | D10: =IF($B10="","",IFERROR($C10/SUM(Expenses!$D$2:$D$500),0)) | E10: =IF($B10="","",$C10*(12/MAX(1,SUMPRODUCT((Expenses!$I$2:$I$500<>"")/COUNTIF(Expenses!$I$2:$I$500,Expenses!$I$2:$I$500&""))))) | G10: Wife | H10: =SUMIF(Expenses!$E$2:$E$500,"Wife",Expenses!$D$2:$D$500) | I10: =SUM(Expenses!$N$2:$N$500)
B11: =IF(Settings!B5="","",Settings!B5) | C11: =IF($B11="","",SUMIF(Expenses!$C$2:$C$500,$B11,Expenses!$D$2:$D$500)) | D11: =IF($B11="","",IFERROR($C11/SUM(Expenses!$D$2:$D$500),0)) | E11: =IF($B11="","",$C11*(12/MAX(1,SUMPRODUCT((Expenses!$I$2:$I$500<>"")/COUNTIF(Expenses!$I$2:$I$500,Expenses!$I$2:$I$500&""))))) | G11: Shared (joint) | H11: =SUMIF(Expenses!$E$2:$E$500,"Shared",Expenses!$D$2:$D$500) | I11: -
B12: =IF(Settings!B6="","",Settings!B6) | C12: =IF($B12="","",SUMIF(Expenses!$C$2:$C$500,$B12,Expenses!$D$2:$D$500)) | D12: =IF($B12="","",IFERROR($C12/SUM(Expenses!$D$2:$D$500),0)) | E12: =IF($B12="","",$C12*(12/MAX(1,SUMPRODUCT((Expenses!$I$2:$I$500<>"")/COUNTIF(Expenses!$I$2:$I$500,Expenses!$I$2:$I$500&"")))))
B13: =IF(Settings!B7="","",Settings!B7) | C13: =IF($B13="","",SUMIF(Expenses!$C$2:$C$500,$B13,Expenses!$D$2:$D$500)) | D13: =IF($B13="","",IFERROR($C13/SUM(Expenses!$D$2:$D$500),0)) | E13: =IF($B13="","",$C13*(12/MAX(1,SUMPRODUCT((Expenses!$I$2:$I$500<>"")/COUNTIF(Expenses!$I$2:$I$500,Expenses!$I$2:$I$500&""))))) | G13: * personal spends + half of everything marked Shared.
B14: =IF(Settings!B8="","",Settings!B8) | C14: =IF($B14="","",SUMIF(Expenses!$C$2:$C$500,$B14,Expenses!$D$2:$D$500)) | D14: =IF($B14="","",IFERROR($C14/SUM(Expenses!$D$2:$D$500),0)) | E14: =IF($B14="","",$C14*(12/MAX(1,SUMPRODUCT((Expenses!$I$2:$I$500<>"")/COUNTIF(Expenses!$I$2:$I$500,Expenses!$I$2:$I$500&"")))))
B15: =IF(Settings!B9="","",Settings!B9) | C15: =IF($B15="","",SUMIF(Expenses!$C$2:$C$500,$B15,Expenses!$D$2:$D$500)) | D15: =IF($B15="","",IFERROR($C15/SUM(Expenses!$D$2:$D$500),0)) | E15: =IF($B15="","",$C15*(12/MAX(1,SUMPRODUCT((Expenses!$I$2:$I$500<>"")/COUNTIF(Expenses!$I$2:$I$500,Expenses!$I$2:$I$500&""))))) | G15: You owe / (are owed): | I15: =I9-H9
B16: =IF(Settings!B10="","",Settings!B10) | C16: =IF($B16="","",SUMIF(Expenses!$C$2:$C$500,$B16,Expenses!$D$2:$D$500)) | D16: =IF($B16="","",IFERROR($C16/SUM(Expenses!$D$2:$D$500),0)) | E16: =IF($B16="","",$C16*(12/MAX(1,SUMPRODUCT((Expenses!$I$2:$I$500<>"")/COUNTIF(Expenses!$I$2:$I$500,Expenses!$I$2:$I$500&"")))))
B17: =IF(Settings!B11="","",Settings!B11) | C17: =IF($B17="","",SUMIF(Expenses!$C$2:$C$500,$B17,Expenses!$D$2:$D$500)) | D17: =IF($B17="","",IFERROR($C17/SUM(Expenses!$D$2:$D$500),0)) | E17: =IF($B17="","",$C17*(12/MAX(1,SUMPRODUCT((Expenses!$I$2:$I$500<>"")/COUNTIF(Expenses!$I$2:$I$500,Expenses!$I$2:$I$500&"")))))
B18: =IF(Settings!B12="","",Settings!B12) | C18: =IF($B18="","",SUMIF(Expenses!$C$2:$C$500,$B18,Expenses!$D$2:$D$500)) | D18: =IF($B18="","",IFERROR($C18/SUM(Expenses!$D$2:$D$500),0)) | E18: =IF($B18="","",$C18*(12/MAX(1,SUMPRODUCT((Expenses!$I$2:$I$500<>"")/COUNTIF(Expenses!$I$2:$I$500,Expenses!$I$2:$I$500&""))))) | G18: Month | H18: Total | I18: Eating Out
B19: =IF(Settings!B13="","",Settings!B13) | C19: =IF($B19="","",SUMIF(Expenses!$C$2:$C$500,$B19,Expenses!$D$2:$D$500)) | D19: =IF($B19="","",IFERROR($C19/SUM(Expenses!$D$2:$D$500),0)) | E19: =IF($B19="","",$C19*(12/MAX(1,SUMPRODUCT((Expenses!$I$2:$I$500<>"")/COUNTIF(Expenses!$I$2:$I$500,Expenses!$I$2:$I$500&""))))) | G19: 2026-04 | H19: =SUMIF(Expenses!$I$2:$I$500,$G19,Expenses!$D$2:$D$500) | I19: =SUMIFS(Expenses!$D$2:$D$500,Expenses!$I$2:$I$500,$G19,Expenses!$C$2:$C$500,"Eating Out / Delivery")
B20: =IF(Settings!B14="","",Settings!B14) | C20: =IF($B20="","",SUMIF(Expenses!$C$2:$C$500,$B20,Expenses!$D$2:$D$500)) | D20: =IF($B20="","",IFERROR($C20/SUM(Expenses!$D$2:$D$500),0)) | E20: =IF($B20="","",$C20*(12/MAX(1,SUMPRODUCT((Expenses!$I$2:$I$500<>"")/COUNTIF(Expenses!$I$2:$I$500,Expenses!$I$2:$I$500&""))))) | G20: 2026-05 | H20: =SUMIF(Expenses!$I$2:$I$500,$G20,Expenses!$D$2:$D$500) | I20: =SUMIFS(Expenses!$D$2:$D$500,Expenses!$I$2:$I$500,$G20,Expenses!$C$2:$C$500,"Eating Out / Delivery")
B21: =IF(Settings!B15="","",Settings!B15) | C21: =IF($B21="","",SUMIF(Expenses!$C$2:$C$500,$B21,Expenses!$D$2:$D$500)) | D21: =IF($B21="","",IFERROR($C21/SUM(Expenses!$D$2:$D$500),0)) | E21: =IF($B21="","",$C21*(12/MAX(1,SUMPRODUCT((Expenses!$I$2:$I$500<>"")/COUNTIF(Expenses!$I$2:$I$500,Expenses!$I$2:$I$500&""))))) | G21: 2026-06 | H21: =SUMIF(Expenses!$I$2:$I$500,$G21,Expenses!$D$2:$D$500) | I21: =SUMIFS(Expenses!$D$2:$D$500,Expenses!$I$2:$I$500,$G21,Expenses!$C$2:$C$500,"Eating Out / Delivery")
B22: =IF(Settings!B16="","",Settings!B16) | C22: =IF($B22="","",SUMIF(Expenses!$C$2:$C$500,$B22,Expenses!$D$2:$D$500)) | D22: =IF($B22="","",IFERROR($C22/SUM(Expenses!$D$2:$D$500),0)) | E22: =IF($B22="","",$C22*(12/MAX(1,SUMPRODUCT((Expenses!$I$2:$I$500<>"")/COUNTIF(Expenses!$I$2:$I$500,Expenses!$I$2:$I$500&""))))) | G22: 2026-07 | H22: =SUMIF(Expenses!$I$2:$I$500,$G22,Expenses!$D$2:$D$500) | I22: =SUMIFS(Expenses!$D$2:$D$500,Expenses!$I$2:$I$500,$G22,Expenses!$C$2:$C$500,"Eating Out / Delivery")
B23: =IF(Settings!B17="","",Settings!B17) | C23: =IF($B23="","",SUMIF(Expenses!$C$2:$C$500,$B23,Expenses!$D$2:$D$500)) | D23: =IF($B23="","",IFERROR($C23/SUM(Expenses!$D$2:$D$500),0)) | E23: =IF($B23="","",$C23*(12/MAX(1,SUMPRODUCT((Expenses!$I$2:$I$500<>"")/COUNTIF(Expenses!$I$2:$I$500,Expenses!$I$2:$I$500&""))))) | G23: 2026-08 | H23: =SUMIF(Expenses!$I$2:$I$500,$G23,Expenses!$D$2:$D$500) | I23: =SUMIFS(Expenses!$D$2:$D$500,Expenses!$I$2:$I$500,$G23,Expenses!$C$2:$C$500,"Eating Out / Delivery")
B24: =IF(Settings!B18="","",Settings!B18) | C24: =IF($B24="","",SUMIF(Expenses!$C$2:$C$500,$B24,Expenses!$D$2:$D$500)) | D24: =IF($B24="","",IFERROR($C24/SUM(Expenses!$D$2:$D$500),0)) | E24: =IF($B24="","",$C24*(12/MAX(1,SUMPRODUCT((Expenses!$I$2:$I$500<>"")/COUNTIF(Expenses!$I$2:$I$500,Expenses!$I$2:$I$500&""))))) | G24: 2026-09 | H24: =SUMIF(Expenses!$I$2:$I$500,$G24,Expenses!$D$2:$D$500) | I24: =SUMIFS(Expenses!$D$2:$D$500,Expenses!$I$2:$I$500,$G24,Expenses!$C$2:$C$500,"Eating Out / Delivery")
B25: =IF(Settings!B19="","",Settings!B19) | C25: =IF($B25="","",SUMIF(Expenses!$C$2:$C$500,$B25,Expenses!$D$2:$D$500)) | D25: =IF($B25="","",IFERROR($C25/SUM(Expenses!$D$2:$D$500),0)) | E25: =IF($B25="","",$C25*(12/MAX(1,SUMPRODUCT((Expenses!$I$2:$I$500<>"")/COUNTIF(Expenses!$I$2:$I$500,Expenses!$I$2:$I$500&"")))))
B26: =IF(Settings!B20="","",Settings!B20) | C26: =IF($B26="","",SUMIF(Expenses!$C$2:$C$500,$B26,Expenses!$D$2:$D$500)) | D26: =IF($B26="","",IFERROR($C26/SUM(Expenses!$D$2:$D$500),0)) | E26: =IF($B26="","",$C26*(12/MAX(1,SUMPRODUCT((Expenses!$I$2:$I$500<>"")/COUNTIF(Expenses!$I$2:$I$500,Expenses!$I$2:$I$500&"")))))
B27: =IF(Settings!B21="","",Settings!B21) | C27: =IF($B27="","",SUMIF(Expenses!$C$2:$C$500,$B27,Expenses!$D$2:$D$500)) | D27: =IF($B27="","",IFERROR($C27/SUM(Expenses!$D$2:$D$500),0)) | E27: =IF($B27="","",$C27*(12/MAX(1,SUMPRODUCT((Expenses!$I$2:$I$500<>"")/COUNTIF(Expenses!$I$2:$I$500,Expenses!$I$2:$I$500&"")))))
B28: =IF(Settings!B22="","",Settings!B22) | C28: =IF($B28="","",SUMIF(Expenses!$C$2:$C$500,$B28,Expenses!$D$2:$D$500)) | D28: =IF($B28="","",IFERROR($C28/SUM(Expenses!$D$2:$D$500),0)) | E28: =IF($B28="","",$C28*(12/MAX(1,SUMPRODUCT((Expenses!$I$2:$I$500<>"")/COUNTIF(Expenses!$I$2:$I$500,Expenses!$I$2:$I$500&"")))))
B29: =IF(Settings!B23="","",Settings!B23) | C29: =IF($B29="","",SUMIF(Expenses!$C$2:$C$500,$B29,Expenses!$D$2:$D$500)) | D29: =IF($B29="","",IFERROR($C29/SUM(Expenses!$D$2:$D$500),0)) | E29: =IF($B29="","",$C29*(12/MAX(1,SUMPRODUCT((Expenses!$I$2:$I$500<>"")/COUNTIF(Expenses!$I$2:$I$500,Expenses!$I$2:$I$500&"")))))
B30: =IF(Settings!B24="","",Settings!B24) | C30: =IF($B30="","",SUMIF(Expenses!$C$2:$C$500,$B30,Expenses!$D$2:$D$500)) | D30: =IF($B30="","",IFERROR($C30/SUM(Expenses!$D$2:$D$500),0)) | E30: =IF($B30="","",$C30*(12/MAX(1,SUMPRODUCT((Expenses!$I$2:$I$500<>"")/COUNTIF(Expenses!$I$2:$I$500,Expenses!$I$2:$I$500&"")))))
B31: =IF(Settings!B25="","",Settings!B25) | C31: =IF($B31="","",SUMIF(Expenses!$C$2:$C$500,$B31,Expenses!$D$2:$D$500)) | D31: =IF($B31="","",IFERROR($C31/SUM(Expenses!$D$2:$D$500),0)) | E31: =IF($B31="","",$C31*(12/MAX(1,SUMPRODUCT((Expenses!$I$2:$I$500<>"")/COUNTIF(Expenses!$I$2:$I$500,Expenses!$I$2:$I$500&"")))))
B32: =IF(Settings!B26="","",Settings!B26) | C32: =IF($B32="","",SUMIF(Expenses!$C$2:$C$500,$B32,Expenses!$D$2:$D$500)) | D32: =IF($B32="","",IFERROR($C32/SUM(Expenses!$D$2:$D$500),0)) | E32: =IF($B32="","",$C32*(12/MAX(1,SUMPRODUCT((Expenses!$I$2:$I$500<>"")/COUNTIF(Expenses!$I$2:$I$500,Expenses!$I$2:$I$500&"")))))
B33: =IF(Settings!B27="","",Settings!B27) | C33: =IF($B33="","",SUMIF(Expenses!$C$2:$C$500,$B33,Expenses!$D$2:$D$500)) | D33: =IF($B33="","",IFERROR($C33/SUM(Expenses!$D$2:$D$500),0)) | E33: =IF($B33="","",$C33*(12/MAX(1,SUMPRODUCT((Expenses!$I$2:$I$500<>"")/COUNTIF(Expenses!$I$2:$I$500,Expenses!$I$2:$I$500&"")))))
B34: =IF(Settings!B28="","",Settings!B28) | C34: =IF($B34="","",SUMIF(Expenses!$C$2:$C$500,$B34,Expenses!$D$2:$D$500)) | D34: =IF($B34="","",IFERROR($C34/SUM(Expenses!$D$2:$D$500),0)) | E34: =IF($B34="","",$C34*(12/MAX(1,SUMPRODUCT((Expenses!$I$2:$I$500<>"")/COUNTIF(Expenses!$I$2:$I$500,Expenses!$I$2:$I$500&"")))))
B35: =IF(Settings!B29="","",Settings!B29) | C35: =IF($B35="","",SUMIF(Expenses!$C$2:$C$500,$B35,Expenses!$D$2:$D$500)) | D35: =IF($B35="","",IFERROR($C35/SUM(Expenses!$D$2:$D$500),0)) | E35: =IF($B35="","",$C35*(12/MAX(1,SUMPRODUCT((Expenses!$I$2:$I$500<>"")/COUNTIF(Expenses!$I$2:$I$500,Expenses!$I$2:$I$500&"")))))
B36: =IF(Settings!B30="","",Settings!B30) | C36: =IF($B36="","",SUMIF(Expenses!$C$2:$C$500,$B36,Expenses!$D$2:$D$500)) | D36: =IF($B36="","",IFERROR($C36/SUM(Expenses!$D$2:$D$500),0)) | E36: =IF($B36="","",$C36*(12/MAX(1,SUMPRODUCT((Expenses!$I$2:$I$500<>"")/COUNTIF(Expenses!$I$2:$I$500,Expenses!$I$2:$I$500&"")))))
... B48: =IF(Settings!B42="","",Settings!B42) | C48: =IF($B48="","",SUMIF(Expenses!$C$2:$C$500,$B48,Expenses!$D$2:$D$500)) | D48: =IF($B48="","",IFERROR($C48/SUM(Expenses!$D$2:$D$500),0)) | E48: =IF($B48="","",$C48*(12/MAX(1,SUMPRODUCT((Expenses!$I$2:$I$500<>"")/COUNTIF(Expenses!$I$2:$I$500,Expenses!$I$2:$I$500&"")))))
B49: TOTAL | C49: =SUM(C9:C48) | E49: =SUM(E9:E48)
B51: Habit Insights
B52: Times we ordered out | E52: =COUNTIF(Expenses!$C$2:$C$500,"Eating Out / Delivery")
B53: Spent on eating out | E53: =SUMIF(Expenses!$C$2:$C$500,"Eating Out / Delivery",Expenses!$D$2:$D$500)
B54: Eating out per month | E54: =IFERROR(COUNTIF(Expenses!$C$2:$C$500,"Eating Out / Delivery")/MAX(1,SUMPRODUCT((Expenses!$I$2:$I$500<>"")/COUNTIF(Expenses!$I$2:$I$500,Expenses!$I$2:$I$500&""))),0)
B55: Avg eating-out ticket | E55: =IFERROR(SUMIF(Expenses!$C$2:$C$500,"Eating Out / Delivery",Expenses!$D$2:$D$500)/COUNTIF(Expenses!$C$2:$C$500,"Eating Out / Delivery"),0)
...

Sheet Monthly Summary
B2: Monthly Summary
B3: Each category's spend by month. Months across the top, categories down the side.
C4: First month: | D4: =IFERROR(TEXT(MIN(Expenses!$A$2:$A$500),"YYYY-MM"),TEXT(TODAY(),"YYYY-MM"))
B5: Category | C5: =TEXT(EDATE(DATE(VALUE(LEFT($D$4,4)),VALUE(RIGHT($D$4,2)),1),0),"YYYY-MM") | D5: =TEXT(EDATE(DATE(VALUE(LEFT($D$4,4)),VALUE(RIGHT($D$4,2)),1),1),"YYYY-MM") | E5: =TEXT(EDATE(DATE(VALUE(LEFT($D$4,4)),VALUE(RIGHT($D$4,2)),1),2),"YYYY-MM") | F5: =TEXT(EDATE(DATE(VALUE(LEFT($D$4,4)),VALUE(RIGHT($D$4,2)),1),3),"YYYY-MM") | G5: =TEXT(EDATE(DATE(VALUE(LEFT($D$4,4)),VALUE(RIGHT($D$4,2)),1),4),"YYYY-MM") | H5: =TEXT(EDATE(DATE(VALUE(LEFT($D$4,4)),VALUE(RIGHT($D$4,2)),1),5),"YYYY-MM") | I5: =TEXT(EDATE(DATE(VALUE(LEFT($D$4,4)),VALUE(RIGHT($D$4,2)),1),6),"YYYY-MM") | J5: =TEXT(EDATE(DATE(VALUE(LEFT($D$4,4)),VALUE(RIGHT($D$4,2)),1),7),"YYYY-MM") | K5: =TEXT(EDATE(DATE(VALUE(LEFT($D$4,4)),VALUE(RIGHT($D$4,2)),1),8),"YYYY-MM") | L5: =TEXT(EDATE(DATE(VALUE(LEFT($D$4,4)),VALUE(RIGHT($D$4,2)),1),9),"YYYY-MM") | M5: =TEXT(EDATE(DATE(VALUE(LEFT($D$4,4)),VALUE(RIGHT($D$4,2)),1),10),"YYYY-MM") | N5: =TEXT(EDATE(DATE(VALUE(LEFT($D$4,4)),VALUE(RIGHT($D$4,2)),1),11),"YYYY-MM") | O5: Total
B6: =IF(Settings!B3="","",Settings!B3) | C6: =IF($B6="","",SUMIFS(Expenses!$D$2:$D$500,Expenses!$C$2:$C$500,$B6,Expenses!$I$2:$I$500,C$5)) | D6: =IF($B6="","",SUMIFS(Expenses!$D$2:$D$500,Expenses!$C$2:$C$500,$B6,Expenses!$I$2:$I$500,D$5)) | E6: =IF($B6="","",SUMIFS(Expenses!$D$2:$D$500,Expenses!$C$2:$C$500,$B6,Expenses!$I$2:$I$500,E$5)) | F6: =IF($B6="","",SUMIFS(Expenses!$D$2:$D$500,Expenses!$C$2:$C$500,$B6,Expenses!$I$2:$I$500,F$5)) | G6: =IF($B6="","",SUMIFS(Expenses!$D$2:$D$500,Expenses!$C$2:$C$500,$B6,Expenses!$I$2:$I$500,G$5)) | H6: =IF($B6="","",SUMIFS(Expenses!$D$2:$D$500,Expenses!$C$2:$C$500,$B6,Expenses!$I$2:$I$500,H$5)) | I6: =IF($B6="","",SUMIFS(Expenses!$D$2:$D$500,Expenses!$C$2:$C$500,$B6,Expenses!$I$2:$I$500,I$5)) | J6: =IF($B6="","",SUMIFS(Expenses!$D$2:$D$500,Expenses!$C$2:$C$500,$B6,Expenses!$I$2:$I$500,J$5)) | ... N6: =IF($B6="","",SUMIFS(Expenses!$D$2:$D$500,Expenses!$C$2:$C$500,$B6,Expenses!$I$2:$I$500,N$5)) | O6: =IF($B6="","",SUM(C6:N6))
B7: =IF(Settings!B4="","",Settings!B4) | C7: =IF($B7="","",SUMIFS(Expenses!$D$2:$D$500,Expenses!$C$2:$C$500,$B7,Expenses!$I$2:$I$500,C$5)) | D7: =IF($B7="","",SUMIFS(Expenses!$D$2:$D$500,Expenses!$C$2:$C$500,$B7,Expenses!$I$2:$I$500,D$5)) | E7: =IF($B7="","",SUMIFS(Expenses!$D$2:$D$500,Expenses!$C$2:$C$500,$B7,Expenses!$I$2:$I$500,E$5)) | F7: =IF($B7="","",SUMIFS(Expenses!$D$2:$D$500,Expenses!$C$2:$C$500,$B7,Expenses!$I$2:$I$500,F$5)) | G7: =IF($B7="","",SUMIFS(Expenses!$D$2:$D$500,Expenses!$C$2:$C$500,$B7,Expenses!$I$2:$I$500,G$5)) | H7: =IF($B7="","",SUMIFS(Expenses!$D$2:$D$500,Expenses!$C$2:$C$500,$B7,Expenses!$I$2:$I$500,H$5)) | I7: =IF($B7="","",SUMIFS(Expenses!$D$2:$D$500,Expenses!$C$2:$C$500,$B7,Expenses!$I$2:$I$500,I$5)) | J7: =IF($B7="","",SUMIFS(Expenses!$D$2:$D$500,Expenses!$C$2:$C$500,$B7,Expenses!$I$2:$I$500,J$5)) | ... N7: =IF($B7="","",SUMIFS(Expenses!$D$2:$D$500,Expenses!$C$2:$C$500,$B7,Expenses!$I$2:$I$500,N$5)) | O7: =IF($B7="","",SUM(C7:N7))
B8: =IF(Settings!B5="","",Settings!B5) | C8: =IF($B8="","",SUMIFS(Expenses!$D$2:$D$500,Expenses!$C$2:$C$500,$B8,Expenses!$I$2:$I$500,C$5)) | D8: =IF($B8="","",SUMIFS(Expenses!$D$2:$D$500,Expenses!$C$2:$C$500,$B8,Expenses!$I$2:$I$500,D$5)) | E8: =IF($B8="","",SUMIFS(Expenses!$D$2:$D$500,Expenses!$C$2:$C$500,$B8,Expenses!$I$2:$I$500,E$5)) | F8: =IF($B8="","",SUMIFS(Expenses!$D$2:$D$500,Expenses!$C$2:$C$500,$B8,Expenses!$I$2:$I$500,F$5)) | G8: =IF($B8="","",SUMIFS(Expenses!$D$2:$D$500,Expenses!$C$2:$C$500,$B8,Expenses!$I$2:$I$500,G$5)) | H8: =IF($B8="","",SUMIFS(Expenses!$D$2:$D$500,Expenses!$C$2:$C$500,$B8,Expenses!$I$2:$I$500,H$5)) | I8: =IF($B8="","",SUMIFS(Expenses!$D$2:$D$500,Expenses!$C$2:$C$500,$B8,Expenses!$I$2:$I$500,I$5)) | J8: =IF($B8="","",SUMIFS(Expenses!$D$2:$D$500,Expenses!$C$2:$C$500,$B8,Expenses!$I$2:$I$500,J$5)) | ... N8: =IF($B8="","",SUMIFS(Expenses!$D$2:$D$500,Expenses!$C$2:$C$500,$B8,Expenses!$I$2:$I$500,N$5)) | O8: =IF($B8="","",SUM(C8:N8))
B9: =IF(Settings!B6="","",Settings!B6) | C9: =IF($B9="","",SUMIFS(Expenses!$D$2:$D$500,Expenses!$C$2:$C$500,$B9,Expenses!$I$2:$I$500,C$5)) | D9: =IF($B9="","",SUMIFS(Expenses!$D$2:$D$500,Expenses!$C$2:$C$500,$B9,Expenses!$I$2:$I$500,D$5)) | E9: =IF($B9="","",SUMIFS(Expenses!$D$2:$D$500,Expenses!$C$2:$C$500,$B9,Expenses!$I$2:$I$500,E$5)) | F9: =IF($B9="","",SUMIFS(Expenses!$D$2:$D$500,Expenses!$C$2:$C$500,$B9,Expenses!$I$2:$I$500,F$5)) | G9: =IF($B9="","",SUMIFS(Expenses!$D$2:$D$500,Expenses!$C$2:$C$500,$B9,Expenses!$I$2:$I$500,G$5)) | H9: =IF($B9="","",SUMIFS(Expenses!$D$2:$D$500,Expenses!$C$2:$C$500,$B9,Expenses!$I$2:$I$500,H$5)) | I9: =IF($B9="","",SUMIFS(Expenses!$D$2:$D$500,Expenses!$C$2:$C$500,$B9,Expenses!$I$2:$I$500,I$5)) | J9: =IF($B9="","",SUMIFS(Expenses!$D$2:$D$500,Expenses!$C$2:$C$500,$B9,Expenses!$I$2:$I$500,J$5)) | ... N9: =IF($B9="","",SUMIFS(Expenses!$D$2:$D$500,Expenses!$C$2:$C$500,$B9,Expenses!$I$2:$I$500,N$5)) | O9: =IF($B9="","",SUM(C9:N9))
B10: =IF(Settings!B7="","",Settings!B7) | C10: =IF($B10="","",SUMIFS(Expenses!$D$2:$D$500,Expenses!$C$2:$C$500,$B10,Expenses!$I$2:$I$500,C$5)) | D10: =IF($B10="","",SUMIFS(Expenses!$D$2:$D$500,Expenses!$C$2:$C$500,$B10,Expenses!$I$2:$I$500,D$5)) | E10: =IF($B10="","",SUMIFS(Expenses!$D$2:$D$500,Expenses!$C$2:$C$500,$B10,Expenses!$I$2:$I$500,E$5)) | F10: =IF($B10="","",SUMIFS(Expenses!$D$2:$D$500,Expenses!$C$2:$C$500,$B10,Expenses!$I$2:$I$500,F$5)) | G10: =IF($B10="","",SUMIFS(Expenses!$D$2:$D$500,Expenses!$C$2:$C$500,$B10,Expenses!$I$2:$I$500,G$5)) | H10: =IF($B10="","",SUMIFS(Expenses!$D$2:$D$500,Expenses!$C$2:$C$500,$B10,Expenses!$I$2:$I$500,H$5)) | I10: =IF($B10="","",SUMIFS(Expenses!$D$2:$D$500,Expenses!$C$2:$C$500,$B10,Expenses!$I$2:$I$500,I$5)) | J10: =IF($B10="","",SUMIFS(Expenses!$D$2:$D$500,Expenses!$C$2:$C$500,$B10,Expenses!$I$2:$I$500,J$5)) | ... N10: =IF($B10="","",SUMIFS(Expenses!$D$2:$D$500,Expenses!$C$2:$C$500,$B10,Expenses!$I$2:$I$500,N$5)) | O10: =IF($B10="","",SUM(C10:N10))
B11: =IF(Settings!B8="","",Settings!B8) | C11: =IF($B11="","",SUMIFS(Expenses!$D$2:$D$500,Expenses!$C$2:$C$500,$B11,Expenses!$I$2:$I$500,C$5)) | D11: =IF($B11="","",SUMIFS(Expenses!$D$2:$D$500,Expenses!$C$2:$C$500,$B11,Expenses!$I$2:$I$500,D$5)) | E11: =IF($B11="","",SUMIFS(Expenses!$D$2:$D$500,Expenses!$C$2:$C$500,$B11,Expenses!$I$2:$I$500,E$5)) | F11: =IF($B11="","",SUMIFS(Expenses!$D$2:$D$500,Expenses!$C$2:$C$500,$B11,Expenses!$I$2:$I$500,F$5)) | G11: =IF($B11="","",SUMIFS(Expenses!$D$2:$D$500,Expenses!$C$2:$C$500,$B11,Expenses!$I$2:$I$500,G$5)) | H11: =IF($B11="","",SUMIFS(Expenses!$D$2:$D$500,Expenses!$C$2:$C$500,$B11,Expenses!$I$2:$I$500,H$5)) | I11: =IF($B11="","",SUMIFS(Expenses!$D$2:$D$500,Expenses!$C$2:$C$500,$B11,Expenses!$I$2:$I$500,I$5)) | J11: =IF($B11="","",SUMIFS(Expenses!$D$2:$D$500,Expenses!$C$2:$C$500,$B11,Expenses!$I$2:$I$500,J$5)) | ... N11: =IF($B11="","",SUMIFS(Expenses!$D$2:$D$500,Expenses!$C$2:$C$500,$B11,Expenses!$I$2:$I$500,N$5)) | O11: =IF($B11="","",SUM(C11:N11))
B12: =IF(Settings!B9="","",Settings!B9) | C12: =IF($B12="","",SUMIFS(Expenses!$D$2:$D$500,Expenses!$C$2:$C$500,$B12,Expenses!$I$2:$I$500,C$5)) | D12: =IF($B12="","",SUMIFS(Expenses!$D$2:$D$500,Expenses!$C$2:$C$500,$B12,Expenses!$I$2:$I$500,D$5)) | E12: =IF($B12="","",SUMIFS(Expenses!$D$2:$D$500,Expenses!$C$2:$C$500,$B12,Expenses!$I$2:$I$500,E$5)) | F12: =IF($B12="","",SUMIFS(Expenses!$D$2:$D$500,Expenses!$C$2:$C$500,$B12,Expenses!$I$2:$I$500,F$5)) | G12: =IF($B12="","",SUMIFS(Expenses!$D$2:$D$500,Expenses!$C$2:$C$500,$B12,Expenses!$I$2:$I$500,G$5)) | H12: =IF($B12="","",SUMIFS(Expenses!$D$2:$D$500,Expenses!$C$2:$C$500,$B12,Expenses!$I$2:$I$500,H$5)) | I12: =IF($B12="","",SUMIFS(Expenses!$D$2:$D$500,Expenses!$C$2:$C$500,$B12,Expenses!$I$2:$I$500,I$5)) | J12: =IF($B12="","",SUMIFS(Expenses!$D$2:$D$500,Expenses!$C$2:$C$500,$B12,Expenses!$I$2:$I$500,J$5)) | ... N12: =IF($B12="","",SUMIFS(Expenses!$D$2:$D$500,Expenses!$C$2:$C$500,$B12,Expenses!$I$2:$I$500,N$5)) | O12: =IF($B12="","",SUM(C12:N12))
B13: =IF(Settings!B10="","",Settings!B10) | C13: =IF($B13="","",SUMIFS(Expenses!$D$2:$D$500,Expenses!$C$2:$C$500,$B13,Expenses!$I$2:$I$500,C$5)) | D13: =IF($B13="","",SUMIFS(Expenses!$D$2:$D$500,Expenses!$C$2:$C$500,$B13,Expenses!$I$2:$I$500,D$5)) | E13: =IF($B13="","",SUMIFS(Expenses!$D$2:$D$500,Expenses!$C$2:$C$500,$B13,Expenses!$I$2:$I$500,E$5)) | F13: =IF($B13="","",SUMIFS(Expenses!$D$2:$D$500,Expenses!$C$2:$C$500,$B13,Expenses!$I$2:$I$500,F$5)) | G13: =IF($B13="","",SUMIFS(Expenses!$D$2:$D$500,Expenses!$C$2:$C$500,$B13,Expenses!$I$2:$I$500,G$5)) | H13: =IF($B13="","",SUMIFS(Expenses!$D$2:$D$500,Expenses!$C$2:$C$500,$B13,Expenses!$I$2:$I$500,H$5)) | I13: =IF($B13="","",SUMIFS(Expenses!$D$2:$D$500,Expenses!$C$2:$C$500,$B13,Expenses!$I$2:$I$500,I$5)) | J13: =IF($B13="","",SUMIFS(Expenses!$D$2:$D$500,Expenses!$C$2:$C$500,$B13,Expenses!$I$2:$I$500,J$5)) | ... N13: =IF($B13="","",SUMIFS(Expenses!$D$2:$D$500,Expenses!$C$2:$C$500,$B13,Expenses!$I$2:$I$500,N$5)) | O13: =IF($B13="","",SUM(C13:N13))
B14: =IF(Settings!B11="","",Settings!B11) | C14: =IF($B14="","",SUMIFS(Expenses!$D$2:$D$500,Expenses!$C$2:$C$500,$B14,Expenses!$I$2:$I$500,C$5)) | D14: =IF($B14="","",SUMIFS(Expenses!$D$2:$D$500,Expenses!$C$2:$C$500,$B14,Expenses!$I$2:$I$500,D$5)) | E14: =IF($B14="","",SUMIFS(Expenses!$D$2:$D$500,Expenses!$C$2:$C$500,$B14,Expenses!$I$2:$I$500,E$5)) | F14: =IF($B14="","",SUMIFS(Expenses!$D$2:$D$500,Expenses!$C$2:$C$500,$B14,Expenses!$I$2:$I$500,F$5)) | G14: =IF($B14="","",SUMIFS(Expenses!$D$2:$D$500,Expenses!$C$2:$C$500,$B14,Expenses!$I$2:$I$500,G$5)) | H14: =IF($B14="","",SUMIFS(Expenses!$D$2:$D$500,Expenses!$C$2:$C$500,$B14,Expenses!$I$2:$I$500,H$5)) | I14: =IF($B14="","",SUMIFS(Expenses!$D$2:$D$500,Expenses!$C$2:$C$500,$B14,Expenses!$I$2:$I$500,I$5)) | J14: =IF($B14="","",SUMIFS(Expenses!$D$2:$D$500,Expenses!$C$2:$C$500,$B14,Expenses!$I$2:$I$500,J$5)) | ... N14: =IF($B14="","",SUMIFS(Expenses!$D$2:$D$500,Expenses!$C$2:$C$500,$B14,Expenses!$I$2:$I$500,N$5)) | O14: =IF($B14="","",SUM(C14:N14))
B15: =IF(Settings!B12="","",Settings!B12) | C15: =IF($B15="","",SUMIFS(Expenses!$D$2:$D$500,Expenses!$C$2:$C$500,$B15,Expenses!$I$2:$I$500,C$5)) | D15: =IF($B15="","",SUMIFS(Expenses!$D$2:$D$500,Expenses!$C$2:$C$500,$B15,Expenses!$I$2:$I$500,D$5)) | E15: =IF($B15="","",SUMIFS(Expenses!$D$2:$D$500,Expenses!$C$2:$C$500,$B15,Expenses!$I$2:$I$500,E$5)) | F15: =IF($B15="","",SUMIFS(Expenses!$D$2:$D$500,Expenses!$C$2:$C$500,$B15,Expenses!$I$2:$I$500,F$5)) | G15: =IF($B15="","",SUMIFS(Expenses!$D$2:$D$500,Expenses!$C$2:$C$500,$B15,Expenses!$I$2:$I$500,G$5)) | H15: =IF($B15="","",SUMIFS(Expenses!$D$2:$D$500,Expenses!$C$2:$C$500,$B15,Expenses!$I$2:$I$500,H$5)) | I15: =IF($B15="","",SUMIFS(Expenses!$D$2:$D$500,Expenses!$C$2:$C$500,$B15,Expenses!$I$2:$I$500,I$5)) | J15: =IF($B15="","",SUMIFS(Expenses!$D$2:$D$500,Expenses!$C$2:$C$500,$B15,Expenses!$I$2:$I$500,J$5)) | ... N15: =IF($B15="","",SUMIFS(Expenses!$D$2:$D$500,Expenses!$C$2:$C$500,$B15,Expenses!$I$2:$I$500,N$5)) | O15: =IF($B15="","",SUM(C15:N15))
B16: =IF(Settings!B13="","",Settings!B13) | C16: =IF($B16="","",SUMIFS(Expenses!$D$2:$D$500,Expenses!$C$2:$C$500,$B16,Expenses!$I$2:$I$500,C$5)) | D16: =IF($B16="","",SUMIFS(Expenses!$D$2:$D$500,Expenses!$C$2:$C$500,$B16,Expenses!$I$2:$I$500,D$5)) | E16: =IF($B16="","",SUMIFS(Expenses!$D$2:$D$500,Expenses!$C$2:$C$500,$B16,Expenses!$I$2:$I$500,E$5)) | F16: =IF($B16="","",SUMIFS(Expenses!$D$2:$D$500,Expenses!$C$2:$C$500,$B16,Expenses!$I$2:$I$500,F$5)) | G16: =IF($B16="","",SUMIFS(Expenses!$D$2:$D$500,Expenses!$C$2:$C$500,$B16,Expenses!$I$2:$I$500,G$5)) | H16: =IF($B16="","",SUMIFS(Expenses!$D$2:$D$500,Expenses!$C$2:$C$500,$B16,Expenses!$I$2:$I$500,H$5)) | I16: =IF($B16="","",SUMIFS(Expenses!$D$2:$D$500,Expenses!$C$2:$C$500,$B16,Expenses!$I$2:$I$500,I$5)) | J16: =IF($B16="","",SUMIFS(Expenses!$D$2:$D$500,Expenses!$C$2:$C$500,$B16,Expenses!$I$2:$I$500,J$5)) | ... N16: =IF($B16="","",SUMIFS(Expenses!$D$2:$D$500,Expenses!$C$2:$C$500,$B16,Expenses!$I$2:$I$500,N$5)) | O16: =IF($B16="","",SUM(C16:N16))
B17: =IF(Settings!B14="","",Settings!B14) | C17: =IF($B17="","",SUMIFS(Expenses!$D$2:$D$500,Expenses!$C$2:$C$500,$B17,Expenses!$I$2:$I$500,C$5)) | D17: =IF($B17="","",SUMIFS(Expenses!$D$2:$D$500,Expenses!$C$2:$C$500,$B17,Expenses!$I$2:$I$500,D$5)) | E17: =IF($B17="","",SUMIFS(Expenses!$D$2:$D$500,Expenses!$C$2:$C$500,$B17,Expenses!$I$2:$I$500,E$5)) | F17: =IF($B17="","",SUMIFS(Expenses!$D$2:$D$500,Expenses!$C$2:$C$500,$B17,Expenses!$I$2:$I$500,F$5)) | G17: =IF($B17="","",SUMIFS(Expenses!$D$2:$D$500,Expenses!$C$2:$C$500,$B17,Expenses!$I$2:$I$500,G$5)) | H17: =IF($B17="","",SUMIFS(Expenses!$D$2:$D$500,Expenses!$C$2:$C$500,$B17,Expenses!$I$2:$I$500,H$5)) | I17: =IF($B17="","",SUMIFS(Expenses!$D$2:$D$500,Expenses!$C$2:$C$500,$B17,Expenses!$I$2:$I$500,I$5)) | J17: =IF($B17="","",SUMIFS(Expenses!$D$2:$D$500,Expenses!$C$2:$C$500,$B17,Expenses!$I$2:$I$500,J$5)) | ... N17: =IF($B17="","",SUMIFS(Expenses!$D$2:$D$500,Expenses!$C$2:$C$500,$B17,Expenses!$I$2:$I$500,N$5)) | O17: =IF($B17="","",SUM(C17:N17))
... B45: =IF(Settings!B42="","",Settings!B42) | C45: =IF($B45="","",SUMIFS(Expenses!$D$2:$D$500,Expenses!$C$2:$C$500,$B45,Expenses!$I$2:$I$500,C$5)) | D45: =IF($B45="","",SUMIFS(Expenses!$D$2:$D$500,Expenses!$C$2:$C$500,$B45,Expenses!$I$2:$I$500,D$5)) | E45: =IF($B45="","",SUMIFS(Expenses!$D$2:$D$500,Expenses!$C$2:$C$500,$B45,Expenses!$I$2:$I$500,E$5)) | F45: =IF($B45="","",SUMIFS(Expenses!$D$2:$D$500,Expenses!$C$2:$C$500,$B45,Expenses!$I$2:$I$500,F$5)) | G45: =IF($B45="","",SUMIFS(Expenses!$D$2:$D$500,Expenses!$C$2:$C$500,$B45,Expenses!$I$2:$I$500,G$5)) | H45: =IF($B45="","",SUMIFS(Expenses!$D$2:$D$500,Expenses!$C$2:$C$500,$B45,Expenses!$I$2:$I$500,H$5)) | I45: =IF($B45="","",SUMIFS(Expenses!$D$2:$D$500,Expenses!$C$2:$C$500,$B45,Expenses!$I$2:$I$500,I$5)) | J45: =IF($B45="","",SUMIFS(Expenses!$D$2:$D$500,Expenses!$C$2:$C$500,$B45,Expenses!$I$2:$I$500,J$5)) | ... N45: =IF($B45="","",SUMIFS(Expenses!$D$2:$D$500,Expenses!$C$2:$C$500,$B45,Expenses!$I$2:$I$500,N$5)) | O45: =IF($B45="","",SUM(C45:N45))
B46: TOTAL | C46: =SUM(C6:C45) | D46: =SUM(D6:D45) | E46: =SUM(E6:E45) | F46: =SUM(F6:F45) | G46: =SUM(G6:G45) | H46: =SUM(H6:H45) | I46: =SUM(I6:I45) | J46: =SUM(J6:J45) | ... O46: =SUM(O6:O45)

Sheet Settings
B2: Categories (add / edit here -- app & dashboard follow)
B3: Groceries | D3: People (fixed)
B4: Eating Out / Delivery | D4: You
B5: Blinkit / Quick-commerce | D5: Wife
B6: Baby | D6: Shared
B7: Rent / Housing
B8: Utilities
B9: Transport | D9: Payment methods
B10: Health | D10: UPI
B11: Shopping | D11: Card
B12: Entertainment | D12: Cash
B13: Subscriptions | D13: Net Banking
B14: Travel
B15: Other
B44: Tip: keep names exactly matching what the app sends.

Sheet Read Me
B2: How this workbook works
B5: TABS
B6: - Expenses : one row per expense (the app appends here).
B7: - Settings : the category list. Edit here to add/rename categories.
B8: - Dashboard : totals, category breakdown, split, habits, projections.
B9: - Monthly Summary : category x month grid.
B11: ADDING A CATEGORY
B12: 1. Open Settings, type the new name in the next empty row under 'Categories'.
B13: 2. The Expenses dropdown, Dashboard, and Monthly Summary pick it up automatically.
B15: SPLIT LOGIC
B16: - Shared = belongs to both, divided 50/50 in 'Fair Share'.
B17: - You / Wife = a personal expense for that person only.
... B25: - The phone app will append rows here once the Apps Script bridge is set up.
